[2025-08-27 15:28:00,608] ERROR custom_exception.py (line: 34 - 
        Error in [C:\Users\Anilchoudary R\LLMOPS--Document-Portal\exception\custom_exception.py] at line [29]
        Message : division by zero
        Traceback:
        Traceback (most recent call last):
  File "C:\Users\Anilchoudary R\LLMOPS--Document-Portal\exception\custom_exception.py", line 29, in <module>
    a = 1 / 0
        ~~^~~
ZeroDivisionError: division by zero

        
        )
